<?xml version="1.0" encoding="UTF-8"?>
<!-- Generated by org.testng.reporters.JUnitReportReporter -->
<testsuite skipped="9" hostname="Sraavan-Sumith" name="myTestNG.ExceptionTest" tests="15" failures="0" timestamp="24 Nov 2018 03:27:39 GMT" time="0.054" errors="3">
  <testcase name="test4" time="0.004" classname="myTestNG.ExceptionTest"/>
  <testcase name="test6" time="0.004" classname="myTestNG.ExceptionTest">
    <error type="org.testng.TestException" message="
Method ExceptionTest.test6()[pri:0, instance:myTestNG.ExceptionTest@2eda0940] should have thrown an exception of any of types [class java.lang.ArithmeticException, class java.lang.IllegalArgumentException]">
      <![CDATA[org.testng.TestException: 
Method ExceptionTest.test6()[pri:0, instance:myTestNG.ExceptionTest@2eda0940] should have thrown an exception of any of types [class java.lang.ArithmeticException, class java.lang.IllegalArgumentException]
at org.testng.internal.ExpectedExceptionsHolder.noException(ExpectedExceptionsHolder.java:80)
at org.testng.internal.Invoker.considerExceptions(Invoker.java:1140)
at org.testng.internal.Invoker.invokeMethod(Invoker.java:615)
at org.testng.internal.Invoker.retryFailed(Invoker.java:839)
at org.testng.internal.Invoker.invokeTestMethods(Invoker.java:1010)
at org.testng.internal.TestMethodWorker.invokeTestMethods(TestMethodWorker.java:125)
at org.testng.internal.TestMethodWorker.run(TestMethodWorker.java:109)
at org.testng.TestRunner.privateRun(TestRunner.java:648)
at org.testng.TestRunner.run(TestRunner.java:505)
at org.testng.SuiteRunner.runTest(SuiteRunner.java:455)
at org.testng.SuiteRunner.runSequentially(SuiteRunner.java:450)
at org.testng.SuiteRunner.privateRun(SuiteRunner.java:415)
at org.testng.SuiteRunner.run(SuiteRunner.java:364)
at org.testng.SuiteRunnerWorker.runSuite(SuiteRunnerWorker.java:52)
at org.testng.SuiteRunnerWorker.run(SuiteRunnerWorker.java:84)
at org.testng.TestNG.runSuitesSequentially(TestNG.java:1208)
at org.testng.TestNG.runSuitesLocally(TestNG.java:1137)
at org.testng.TestNG.runSuites(TestNG.java:1049)
at org.testng.TestNG.run(TestNG.java:1017)
at org.testng.remote.AbstractRemoteTestNG.run(AbstractRemoteTestNG.java:114)
at org.testng.remote.RemoteTestNG.initAndRun(RemoteTestNG.java:251)
at org.testng.remote.RemoteTestNG.main(RemoteTestNG.java:77)
]]>
    </error>
  </testcase> <!-- test6 -->
  <testcase name="test5" time="0.003" classname="myTestNG.ExceptionTest"/>
  <testcase name="test1" time="0.003" classname="myTestNG.ExceptionTest">
    <skipped/>
  </testcase> <!-- test1 -->
  <testcase name="test2" time="0.004" classname="myTestNG.ExceptionTest"/>
  <testcase name="test3" time="0.002" classname="myTestNG.ExceptionTest">
    <skipped/>
  </testcase> <!-- test3 -->
  <testcase name="test3" time="0.004" classname="myTestNG.ExceptionTest">
    <skipped/>
  </testcase> <!-- test3 -->
  <testcase name="test1" time="0.001" classname="myTestNG.ExceptionTest">
    <error type="org.testng.TestException" message="
Method ExceptionTest.test1()[pri:0, instance:myTestNG.ExceptionTest@2eda0940] should have thrown an exception of type class java.lang.IllegalArgumentException">
      <![CDATA[org.testng.TestException: 
Method ExceptionTest.test1()[pri:0, instance:myTestNG.ExceptionTest@2eda0940] should have thrown an exception of type class java.lang.IllegalArgumentException
at org.testng.internal.ExpectedExceptionsHolder.noException(ExpectedExceptionsHolder.java:80)
at org.testng.internal.Invoker.considerExceptions(Invoker.java:1140)
at org.testng.internal.Invoker.invokeMethod(Invoker.java:615)
at org.testng.internal.Invoker.retryFailed(Invoker.java:839)
at org.testng.internal.Invoker.invokeTestMethods(Invoker.java:1010)
at org.testng.internal.TestMethodWorker.invokeTestMethods(TestMethodWorker.java:125)
at org.testng.internal.TestMethodWorker.run(TestMethodWorker.java:109)
at org.testng.TestRunner.privateRun(TestRunner.java:648)
at org.testng.TestRunner.run(TestRunner.java:505)
at org.testng.SuiteRunner.runTest(SuiteRunner.java:455)
at org.testng.SuiteRunner.runSequentially(SuiteRunner.java:450)
at org.testng.SuiteRunner.privateRun(SuiteRunner.java:415)
at org.testng.SuiteRunner.run(SuiteRunner.java:364)
at org.testng.SuiteRunnerWorker.runSuite(SuiteRunnerWorker.java:52)
at org.testng.SuiteRunnerWorker.run(SuiteRunnerWorker.java:84)
at org.testng.TestNG.runSuitesSequentially(TestNG.java:1208)
at org.testng.TestNG.runSuitesLocally(TestNG.java:1137)
at org.testng.TestNG.runSuites(TestNG.java:1049)
at org.testng.TestNG.run(TestNG.java:1017)
at org.testng.remote.AbstractRemoteTestNG.run(AbstractRemoteTestNG.java:114)
at org.testng.remote.RemoteTestNG.initAndRun(RemoteTestNG.java:251)
at org.testng.remote.RemoteTestNG.main(RemoteTestNG.java:77)
]]>
    </error>
  </testcase> <!-- test1 -->
  <testcase name="test6" time="0.003" classname="myTestNG.ExceptionTest">
    <skipped/>
  </testcase> <!-- test6 -->
  <testcase name="test3" time="0.006" classname="myTestNG.ExceptionTest">
    <skipped/>
  </testcase> <!-- test3 -->
  <testcase name="test6" time="0.008" classname="myTestNG.ExceptionTest">
    <skipped/>
  </testcase> <!-- test6 -->
  <testcase name="test3" time="0.001" classname="myTestNG.ExceptionTest">
    <error type="org.testng.TestException" message="
Expected exception of type class java.lang.ArithmeticException but got java.lang.IllegalArgumentException: 24 is less than 36">
      <![CDATA[org.testng.TestException: 
Expected exception of type class java.lang.ArithmeticException but got java.lang.IllegalArgumentException: 24 is less than 36
at org.testng.internal.ExpectedExceptionsHolder.wrongException(ExpectedExceptionsHolder.java:68)
at org.testng.internal.Invoker.considerExceptions(Invoker.java:1130)
at org.testng.internal.Invoker.invokeMethod(Invoker.java:615)
at org.testng.internal.Invoker.retryFailed(Invoker.java:839)
at org.testng.internal.Invoker.invokeTestMethods(Invoker.java:1010)
at org.testng.internal.TestMethodWorker.invokeTestMethods(TestMethodWorker.java:125)
at org.testng.internal.TestMethodWorker.run(TestMethodWorker.java:109)
at org.testng.TestRunner.privateRun(TestRunner.java:648)
at org.testng.TestRunner.run(TestRunner.java:505)
at org.testng.SuiteRunner.runTest(SuiteRunner.java:455)
at org.testng.SuiteRunner.runSequentially(SuiteRunner.java:450)
at org.testng.SuiteRunner.privateRun(SuiteRunner.java:415)
at org.testng.SuiteRunner.run(SuiteRunner.java:364)
at org.testng.SuiteRunnerWorker.runSuite(SuiteRunnerWorker.java:52)
at org.testng.SuiteRunnerWorker.run(SuiteRunnerWorker.java:84)
at org.testng.TestNG.runSuitesSequentially(TestNG.java:1208)
at org.testng.TestNG.runSuitesLocally(TestNG.java:1137)
at org.testng.TestNG.runSuites(TestNG.java:1049)
at org.testng.TestNG.run(TestNG.java:1017)
at org.testng.remote.AbstractRemoteTestNG.run(AbstractRemoteTestNG.java:114)
at org.testng.remote.RemoteTestNG.initAndRun(RemoteTestNG.java:251)
at org.testng.remote.RemoteTestNG.main(RemoteTestNG.java:77)
Caused by: java.lang.IllegalArgumentException: 24 is less than 36
at myTestNG.Calculator.div(Calculator.java:61)
at myTestNG.ExceptionTest.test3(ExceptionTest.java:49)
at sun.reflect.NativeMethodAccessorImpl.invoke0(Native Method)
at sun.reflect.NativeMethodAccessorImpl.invoke(Unknown Source)
at sun.reflect.DelegatingMethodAccessorImpl.invoke(Unknown Source)
at java.lang.reflect.Method.invoke(Unknown Source)
at org.testng.internal.MethodInvocationHelper.invokeMethod(MethodInvocationHelper.java:124)
at org.testng.internal.Invoker.invokeMethod(Invoker.java:583)
... 19 more
]]>
    </error>
  </testcase> <!-- test3 -->
  <testcase name="test1" time="0.002" classname="myTestNG.ExceptionTest">
    <skipped/>
  </testcase> <!-- test1 -->
  <testcase name="test1" time="0.001" classname="myTestNG.ExceptionTest">
    <skipped/>
  </testcase> <!-- test1 -->
  <testcase name="test6" time="0.008" classname="myTestNG.ExceptionTest">
    <skipped/>
  </testcase> <!-- test6 -->
</testsuite> <!-- myTestNG.ExceptionTest -->
